Workbook

Sheet Invitati
A1: Nome | B1: Cognome | C1: Fascia | D1: Dieta | E1: Allergia – Glutine (cereali) | F1: Allergia – Crostacei | G1: Allergia – Uova | H1: Allergia – Pesce | I1: Allergia – Arachidi | J1: Allergia – Soia | K1: Allergia – Latte e derivati | L1: Allergia – Frutta a guscio | M1: Allergia – Sedano | N1: Allergia – Senape | O1: Allergia – Sesamo | P1: Allergia – Solfiti | Q1: Allergia – Lupini | R1: Allergia – Molluschi | S1: Intolleranza – Celiachia | T1: Intolleranza – Lattosio | U1: Intolleranza – Nichel | V1: Intolleranza – Istamina | W1: Intolleranza – Fruttosio | X1: Intolleranza – Favismo | Y1: Altre allergie / intolleranze (scrivere) | Z1: Note per la cucina | AA1: Nome completo | AB1: Stato tavolo
A2: Enrico | B2: Leone | C2: Adulto | AA2: =IF(OR(A2<>"",B2<>""),TRIM(A2&" "&B2),"") | AB2: =IF(AA2="","",IF(COUNTIF(Tavoli!$E$2:$AB$41,AA2)=0,"Da assegnare",IF(COUNTIF(Tavoli!$E$2:$AB$41,AA2)>1,"DUPLICATO","Tavolo "&SUMPRODUCT((Tavoli!$E$2:$AB$41=AA2)*Tavoli!$A$2:$A$41))))
A3: Chiara | B3: Lombardo | C3: Adulto | AA3: =IF(OR(A3<>"",B3<>""),TRIM(A3&" "&B3),"") | AB3: =IF(AA3="","",IF(COUNTIF(Tavoli!$E$2:$AB$41,AA3)=0,"Da assegnare",IF(COUNTIF(Tavoli!$E$2:$AB$41,AA3)>1,"DUPLICATO","Tavolo "&SUMPRODUCT((Tavoli!$E$2:$AB$41=AA3)*Tavoli!$A$2:$A$41))))
A4: Elena | B4: Romano | C4: Adulto | N4: X | AA4: =IF(OR(A4<>"",B4<>""),TRIM(A4&" "&B4),"") | AB4: =IF(AA4="","",IF(COUNTIF(Tavoli!$E$2:$AB$41,AA4)=0,"Da assegnare",IF(COUNTIF(Tavoli!$E$2:$AB$41,AA4)>1,"DUPLICATO","Tavolo "&SUMPRODUCT((Tavoli!$E$2:$AB$41=AA4)*Tavoli!$A$2:$A$41))))
A5: Marco | B5: Caruso | C5: Adulto | AA5: =IF(OR(A5<>"",B5<>""),TRIM(A5&" "&B5),"") | AB5: =IF(AA5="","",IF(COUNTIF(Tavoli!$E$2:$AB$41,AA5)=0,"Da assegnare",IF(COUNTIF(Tavoli!$E$2:$AB$41,AA5)>1,"DUPLICATO","Tavolo "&SUMPRODUCT((Tavoli!$E$2:$AB$41=AA5)*Tavoli!$A$2:$A$41))))
A6: Alice | B6: Rinaldi | C6: Adulto | AA6: =IF(OR(A6<>"",B6<>""),TRIM(A6&" "&B6),"") | AB6: =IF(AA6="","",IF(COUNTIF(Tavoli!$E$2:$AB$41,AA6)=0,"Da assegnare",IF(COUNTIF(Tavoli!$E$2:$AB$41,AA6)>1,"DUPLICATO","Tavolo "&SUMPRODUCT((Tavoli!$E$2:$AB$41=AA6)*Tavoli!$A$2:$A$41))))
A7: Federica | B7: Costa | C7: Adulto | Y7: Allergia al kiwi | AA7: =IF(OR(A7<>"",B7<>""),TRIM(A7&" "&B7),"") | AB7: =IF(AA7="","",IF(COUNTIF(Tavoli!$E$2:$AB$41,AA7)=0,"Da assegnare",IF(COUNTIF(Tavoli!$E$2:$AB$41,AA7)>1,"DUPLICATO","Tavolo "&SUMPRODUCT((Tavoli!$E$2:$AB$41=AA7)*Tavoli!$A$2:$A$41))))
A8: Laura | B8: Longo | C8: Adulto | AA8: =IF(OR(A8<>"",B8<>""),TRIM(A8&" "&B8),"") | AB8: =IF(AA8="","",IF(COUNTIF(Tavoli!$E$2:$AB$41,AA8)=0,"Da assegnare",IF(COUNTIF(Tavoli!$E$2:$AB$41,AA8)>1,"DUPLICATO","Tavolo "&SUMPRODUCT((Tavoli!$E$2:$AB$41=AA8)*Tavoli!$A$2:$A$41))))
A9: Giulia | B9: Galli | C9: Adulto | AA9: =IF(OR(A9<>"",B9<>""),TRIM(A9&" "&B9),"") | AB9: =IF(AA9="","",IF(COUNTIF(Tavoli!$E$2:$AB$41,AA9)=0,"Da assegnare",IF(COUNTIF(Tavoli!$E$2:$AB$41,AA9)>1,"DUPLICATO","Tavolo "&SUMPRODUCT((Tavoli!$E$2:$AB$41=AA9)*Tavoli!$A$2:$A$41))))
A10: Daniele | B10: Caruso | C10: Adulto | AA10: =IF(OR(A10<>"",B10<>""),TRIM(A10&" "&B10),"") | AB10: =IF(AA10="","",IF(COUNTIF(Tavoli!$E$2:$AB$41,AA10)=0,"Da assegnare",IF(COUNTIF(Tavoli!$E$2:$AB$41,AA10)>1,"DUPLICATO","Tavolo "&SUMPRODUCT((Tavoli!$E$2:$AB$41=AA10)*Tavoli!$A$2:$A$41))))
A11: Simone | B11: Rossi | C11: Adulto | Z11: Seggiolone per favore | AA11: =IF(OR(A11<>"",B11<>""),TRIM(A11&" "&B11),"") | AB11: =IF(AA11="","",IF(COUNTIF(Tavoli!$E$2:$AB$41,AA11)=0,"Da assegnare",IF(COUNTIF(Tavoli!$E$2:$AB$41,AA11)>1,"DUPLICATO","Tavolo "&SUMPRODUCT((Tavoli!$E$2:$AB$41=AA11)*Tavoli!$A$2:$A$41))))
A12: Gabriele | B12: Rinaldi | C12: Adulto | AA12: =IF(OR(A12<>"",B12<>""),TRIM(A12&" "&B12),"") | AB12: =IF(AA12="","",IF(COUNTIF(Tavoli!$E$2:$AB$41,AA12)=0,"Da assegnare",IF(COUNTIF(Tavoli!$E$2:$AB$41,AA12)>1,"DUPLICATO","Tavolo "&SUMPRODUCT((Tavoli!$E$2:$AB$41=AA12)*Tavoli!$A$2:$A$41))))
A13: Andrea | B13: Greco | C13: Adulto | AA13: =IF(OR(A13<>"",B13<>""),TRIM(A13&" "&B13),"") | AB13: =IF(AA13="","",IF(COUNTIF(Tavoli!$E$2:$AB$41,AA13)=0,"Da assegnare",IF(COUNTIF(Tavoli!$E$2:$AB$41,AA13)>1,"DUPLICATO","Tavolo "&SUMPRODUCT((Tavoli!$E$2:$AB$41=AA13)*Tavoli!$A$2:$A$41))))
A14: Elena | B14: Vitale | C14: Adulto | AA14: =IF(OR(A14<>"",B14<>""),TRIM(A14&" "&B14),"") | AB14: =IF(AA14="","",IF(COUNTIF(Tavoli!$E$2:$AB$41,AA14)=0,"Da assegnare",IF(COUNTIF(Tavoli!$E$2:$AB$41,AA14)>1,"DUPLICATO","Tavolo "&SUMPRODUCT((Tavoli!$E$2:$AB$41=AA14)*Tavoli!$A$2:$A$41))))
A15: Giorgio | B15: Fontana | C15: Adulto | AA15: =IF(OR(A15<>"",B15<>""),TRIM(A15&" "&B15),"") | AB15: =IF(AA15="","",IF(COUNTIF(Tavoli!$E$2:$AB$41,AA15)=0,"Da assegnare",IF(COUNTIF(Tavoli!$E$2:$AB$41,AA15)>1,"DUPLICATO","Tavolo "&SUMPRODUCT((Tavoli!$E$2:$AB$41=AA15)*Tavoli!$A$2:$A$41))))
A16: Giorgio | B16: Gentile | C16: Adulto | AA16: =IF(OR(A16<>"",B16<>""),TRIM(A16&" "&B16),"") | AB16: =IF(AA16="","",IF(COUNTIF(Tavoli!$E$2:$AB$41,AA16)=0,"Da assegnare",IF(COUNTIF(Tavoli!$E$2:$AB$41,AA16)>1,"DUPLICATO","Tavolo "&SUMPRODUCT((Tavoli!$E$2:$AB$41=AA16)*Tavoli!$A$2:$A$41))))
A17: Beatrice | B17: Longo | C17: Adulto | AA17: =IF(OR(A17<>"",B17<>""),TRIM(A17&" "&B17),"") | AB17: =IF(AA17="","",IF(COUNTIF(Tavoli!$E$2:$AB$41,AA17)=0,"Da assegnare",IF(COUNTIF(Tavoli!$E$2:$AB$41,AA17)>1,"DUPLICATO","Tavolo "&SUMPRODUCT((Tavoli!$E$2:$AB$41=AA17)*Tavoli!$A$2:$A$41))))
A18: Paolo | B18: Conti | C18: Adulto | D18: Vegetariano | AA18: =IF(OR(A18<>"",B18<>""),TRIM(A18&" "&B18),"") | AB18: =IF(AA18="","",IF(COUNTIF(Tavoli!$E$2:$AB$41,AA18)=0,"Da assegnare",IF(COUNTIF(Tavoli!$E$2:$AB$41,AA18)>1,"DUPLICATO","Tavolo "&SUMPRODUCT((Tavoli!$E$2:$AB$41=AA18)*Tavoli!$A$2:$A$41))))
A19: Fabio | B19: Colombo | C19: Adulto | K19: X | AA19: =IF(OR(A19<>"",B19<>""),TRIM(A19&" "&B19),"") | AB19: =IF(AA19="","",IF(COUNTIF(Tavoli!$E$2:$AB$41,AA19)=0,"Da assegnare",IF(COUNTIF(Tavoli!$E$2:$AB$41,AA19)>1,"DUPLICATO","Tavolo "&SUMPRODUCT((Tavoli!$E$2:$AB$41=AA19)*Tavoli!$A$2:$A$41))))
A20: Luca | B20: Marino | C20: Adulto | D20: Vegano | U20: X | AA20: =IF(OR(A20<>"",B20<>""),TRIM(A20&" "&B20),"") | AB20: =IF(AA20="","",IF(COUNTIF(Tavoli!$E$2:$AB$41,AA20)=0,"Da assegnare",IF(COUNTIF(Tavoli!$E$2:$AB$41,AA20)>1,"DUPLICATO","Tavolo "&SUMPRODUCT((Tavoli!$E$2:$AB$41=AA20)*Tavoli!$A$2:$A$41))))
A21: Alessio | B21: Caruso | C21: Adulto | AA21: =IF(OR(A21<>"",B21<>""),TRIM(A21&" "&B21),"") | AB21: =IF(AA21="","",IF(COUNTIF(Tavoli!$E$2:$AB$41,AA21)=0,"Da assegnare",IF(COUNTIF(Tavoli!$E$2:$AB$41,AA21)>1,"DUPLICATO","Tavolo "&SUMPRODUCT((Tavoli!$E$2:$AB$41=AA21)*Tavoli!$A$2:$A$41))))
A22: Fabio | B22: Rizzo | C22: Bambino | AA22: =IF(OR(A22<>"",B22<>""),TRIM(A22&" "&B22),"") | AB22: =IF(AA22="","",IF(COUNTIF(Tavoli!$E$2:$AB$41,AA22)=0,"Da assegnare",IF(COUNTIF(Tavoli!$E$2:$AB$41,AA22)>1,"DUPLICATO","Tavolo "&SUMPRODUCT((Tavoli!$E$2:$AB$41=AA22)*Tavoli!$A$2:$A$41))))
A23: Francesca | B23: Martinelli | C23: Adulto | H23: X | U23: X | AA23: =IF(OR(A23<>"",B23<>""),TRIM(A23&" "&B23),"") | AB23: =IF(AA23="","",IF(COUNTIF(Tavoli!$E$2:$AB$41,AA23)=0,"Da assegnare",IF(COUNTIF(Tavoli!$E$2:$AB$41,AA23)>1,"DUPLICATO","Tavolo "&SUMPRODUCT((Tavoli!$E$2:$AB$41=AA23)*Tavoli!$A$2:$A$41))))
A24: Beatrice | B24: Rinaldi | C24: Adulto | AA24: =IF(OR(A24<>"",B24<>""),TRIM(A24&" "&B24),"") | AB24: =IF(AA24="","",IF(COUNTIF(Tavoli!$E$2:$AB$41,AA24)=0,"Da assegnare",IF(COUNTIF(Tavoli!$E$2:$AB$41,AA24)>1,"DUPLICATO","Tavolo "&SUMPRODUCT((Tavoli!$E$2:$AB$41=AA24)*Tavoli!$A$2:$A$41))))
A25: Fabio | B25: Vitale | C25: Adulto | AA25: =IF(OR(A25<>"",B25<>""),TRIM(A25&" "&B25),"") | AB25: =IF(AA25="","",IF(COUNTIF(Tavoli!$E$2:$AB$41,AA25)=0,"Da assegnare",IF(COUNTIF(Tavoli!$E$2:$AB$41,AA25)>1,"DUPLICATO","Tavolo "&SUMPRODUCT((Tavoli!$E$2:$AB$41=AA25)*Tavoli!$A$2:$A$41))))
A26: Beatrice | B26: Luca | C26: Adulto | AA26: =IF(OR(A26<>"",B26<>""),TRIM(A26&" "&B26),"") | AB26: =IF(AA26="","",IF(COUNTIF(Tavoli!$E$2:$AB$41,AA26)=0,"Da assegnare",IF(COUNTIF(Tavoli!$E$2:$AB$41,AA26)>1,"DUPLICATO","Tavolo "&SUMPRODUCT((Tavoli!$E$2:$AB$41=AA26)*Tavoli!$A$2:$A$41))))
A27: Elena | B27: Martini | C27: Adulto | AA27: =IF(OR(A27<>"",B27<>""),TRIM(A27&" "&B27),"") | AB27: =IF(AA27="","",IF(COUNTIF(Tavoli!$E$2:$AB$41,AA27)=0,"Da assegnare",IF(COUNTIF(Tavoli!$E$2:$AB$41,AA27)>1,"DUPLICATO","Tavolo "&SUMPRODUCT((Tavoli!$E$2:$AB$41=AA27)*Tavoli!$A$2:$A$41))))
A28: Beatrice | B28: Greco | C28: Adulto | X28: X | AA28: =IF(OR(A28<>"",B28<>""),TRIM(A28&" "&B28),"") | AB28: =IF(AA28="","",IF(COUNTIF(Tavoli!$E$2:$AB$41,AA28)=0,"Da assegnare",IF(COUNTIF(Tavoli!$E$2:$AB$41,AA28)>1,"DUPLICATO","Tavolo "&SUMPRODUCT((Tavoli!$E$2:$AB$41=AA28)*Tavoli!$A$2:$A$41))))
A29: Giulia | B29: Lombardi | C29: Adulto | AA29: =IF(OR(A29<>"",B29<>""),TRIM(A29&" "&B29),"") | AB29: =IF(AA29="","",IF(COUNTIF(Tavoli!$E$2:$AB$41,AA29)=0,"Da assegnare",IF(COUNTIF(Tavoli!$E$2:$AB$41,AA29)>1,"DUPLICATO","Tavolo "&SUMPRODUCT((Tavoli!$E$2:$AB$41=AA29)*Tavoli!$A$2:$A$41))))
A30: Simone | B30: Lombardo | C30: Adulto | AA30: =IF(OR(A30<>"",B30<>""),TRIM(A30&" "&B30),"") | AB30: =IF(AA30="","",IF(COUNTIF(Tavoli!$E$2:$AB$41,AA30)=0,"Da assegnare",IF(COUNTIF(Tavoli!$E$2:$AB$41,AA30)>1,"DUPLICATO","Tavolo "&SUMPRODUCT((Tavoli!$E$2:$AB$41=AA30)*Tavoli!$A$2:$A$41))))
A31: Davide | B31: Mancini | C31: Adulto | AA31: =IF(OR(A31<>"",B31<>""),TRIM(A31&" "&B31),"") | AB31: =IF(AA31="","",IF(COUNTIF(Tavoli!$E$2:$AB$41,AA31)=0,"Da assegnare",IF(COUNTIF(Tavoli!$E$2:$AB$41,AA31)>1,"DUPLICATO","Tavolo "&SUMPRODUCT((Tavoli!$E$2:$AB$41=AA31)*Tavoli!$A$2:$A$41))))
A32: Marta | B32: Giordano | C32: Adulto | D32: Vegetariano | T32: X | AA32: =IF(OR(A32<>"",B32<>""),TRIM(A32&" "&B32),"") | AB32: =IF(AA32="","",IF(COUNTIF(Tavoli!$E$2:$AB$41,AA32)=0,"Da assegnare",IF(COUNTIF(Tavoli!$E$2:$AB$41,AA32)>1,"DUPLICATO","Tavolo "&SUMPRODUCT((Tavoli!$E$2:$AB$41=AA32)*Tavoli!$A$2:$A$41))))
A33: Simone | B33: Giordano | C33: Bambino | AA33: =IF(OR(A33<>"",B33<>""),TRIM(A33&" "&B33),"") | AB33: =IF(AA33="","",IF(COUNTIF(Tavoli!$E$2:$AB$41,AA33)=0,"Da assegnare",IF(COUNTIF(Tavoli!$E$2:$AB$41,AA33)>1,"DUPLICATO","Tavolo "&SUMPRODUCT((Tavoli!$E$2:$AB$41=AA33)*Tavoli!$A$2:$A$41))))
A34: Alessio | B34: Rizzo | C34: Adulto | E34: X | AA34: =IF(OR(A34<>"",B34<>""),TRIM(A34&" "&B34),"") | AB34: =IF(AA34="","",IF(COUNTIF(Tavoli!$E$2:$AB$41,AA34)=0,"Da assegnare",IF(COUNTIF(Tavoli!$E$2:$AB$41,AA34)>1,"DUPLICATO","Tavolo "&SUMPRODUCT((Tavoli!$E$2:$AB$41=AA34)*Tavoli!$A$2:$A$41))))
A35: Luca | B35: De | C35: Adulto | K35: X | AA35: =IF(OR(A35<>"",B35<>""),TRIM(A35&" "&B35),"") | AB35: =IF(AA35="","",IF(COUNTIF(Tavoli!$E$2:$AB$41,AA35)=0,"Da assegnare",IF(COUNTIF(Tavoli!$E$2:$AB$41,AA35)>1,"DUPLICATO","Tavolo "&SUMPRODUCT((Tavoli!$E$2:$AB$41=AA35)*Tavoli!$A$2:$A$41))))
A36: Francesca | B36: Rossi | C36: Adulto | AA36: =IF(OR(A36<>"",B36<>""),TRIM(A36&" "&B36),"") | AB36: =IF(AA36="","",IF(COUNTIF(Tavoli!$E$2:$AB$41,AA36)=0,"Da assegnare",IF(COUNTIF(Tavoli!$E$2:$AB$41,AA36)>1,"DUPLICATO","Tavolo "&SUMPRODUCT((Tavoli!$E$2:$AB$41=AA36)*Tavoli!$A$2:$A$41))))
A37: Nicola | B37: Coppola | C37: Adulto | AA37: =IF(OR(A37<>"",B37<>""),TRIM(A37&" "&B37),"") | AB37: =IF(AA37="","",IF(COUNTIF(Tavoli!$E$2:$AB$41,AA37)=0,"Da assegnare",IF(COUNTIF(Tavoli!$E$2:$AB$41,AA37)>1,"DUPLICATO","Tavolo "&SUMPRODUCT((Tavoli!$E$2:$AB$41=AA37)*Tavoli!$A$2:$A$41))))
A38: Martina | B38: Caruso | C38: Adulto | D38: Vegano | AA38: =IF(OR(A38<>"",B38<>""),TRIM(A38&" "&B38),"") | AB38: =IF(AA38="","",IF(COUNTIF(Tavoli!$E$2:$AB$41,AA38)=0,"Da assegnare",IF(COUNTIF(Tavoli!$E$2:$AB$41,AA38)>1,"DUPLICATO","Tavolo "&SUMPRODUCT((Tavoli!$E$2:$AB$41=AA38)*Tavoli!$A$2:$A$41))))
A39: Stefano | B39: De | C39: Adulto | AA39: =IF(OR(A39<>"",B39<>""),TRIM(A39&" "&B39),"") | AB39: =IF(AA39="","",IF(COUNTIF(Tavoli!$E$2:$AB$41,AA39)=0,"Da assegnare",IF(COUNTIF(Tavoli!$E$2:$AB$41,AA39)>1,"DUPLICATO","Tavolo "&SUMPRODUCT((Tavoli!$E$2:$AB$41=AA39)*Tavoli!$A$2:$A$41))))
A40: Alessio | B40: Longo | C40: Adulto | AA40: =IF(OR(A40<>"",B40<>""),TRIM(A40&" "&B40),"") | AB40: =IF(AA40="","",IF(COUNTIF(Tavoli!$E$2:$AB$41,AA40)=0,"Da assegnare",IF(COUNTIF(Tavoli!$E$2:$AB$41,AA40)>1,"DUPLICATO","Tavolo "&SUMPRODUCT((Tavoli!$E$2:$AB$41=AA40)*Tavoli!$A$2:$A$41))))
...

Sheet Tavoli
A1: N. tavolo | B1: Nome tavolo (facoltativo) | C1: Forma tavolo | D1: N. posti | E1: Posto 1 | F1: Posto 2 | G1: Posto 3 | H1: Posto 4 | I1: Posto 5 | J1: Posto 6 | K1: Posto 7 | L1: Posto 8 | M1: Posto 9 | N1: Posto 10 | O1: Posto 11 | P1: Posto 12 | Q1: Posto 13 | R1: Posto 14 | S1: Posto 15 | T1: Posto 16 | U1: Posto 17 | V1: Posto 18 | W1: Posto 19 | X1: Posto 20 | Y1: Posto 21 | Z1: Posto 22 | AA1: Posto 23 | AB1: Posto 24 | AC1: Occupati | AD1: Controllo
A2: 1 | B2: Sposi | C2: Tondo | D2: 10 | E2: Enrico Leone | F2: Chiara Lombardo | G2: Elena Romano | H2: Marco Caruso | I2: Alice Rinaldi | J2: Federica Costa | K2: Laura Longo | L2: Giulia Galli | M2: Daniele Caruso | N2: Simone Rossi | AC2: =COUNTA(E2:AB2) | AD2: =IF(AND(C2="",D2="",AC2=0),"",IF(OR(C2="",D2=""),"Indicare forma e posti",IF(AC2>D2,"Troppi invitati",IF(AC2<D2,"Posti liberi: "&(D2-AC2),"OK"))))
A3: 2 | B3: Tavolo 2 | C3: Tondo | D3: 11 | E3: Gabriele Rinaldi | F3: Andrea Greco | G3: Elena Vitale | H3: Giorgio Fontana | I3: Giorgio Gentile | J3: Beatrice Longo | K3: Paolo Conti | L3: Fabio Colombo | M3: Luca Marino | N3: Alessio Caruso | O3: Fabio Rizzo | AC3: =COUNTA(E3:AB3) | AD3: =IF(AND(C3="",D3="",AC3=0),"",IF(OR(C3="",D3=""),"Indicare forma e posti",IF(AC3>D3,"Troppi invitati",IF(AC3<D3,"Posti liberi: "&(D3-AC3),"OK"))))
A4: 3 | B4: Tavolo 3 | C4: Tondo | D4: 9 | E4: Francesca Martinelli | F4: Beatrice Rinaldi | G4: Fabio Vitale | H4: Beatrice Luca | I4: Elena Martini | J4: Beatrice Greco | K4: Giulia Lombardi | L4: Simone Lombardo | M4: Davide Mancini | AC4: =COUNTA(E4:AB4) | AD4: =IF(AND(C4="",D4="",AC4=0),"",IF(OR(C4="",D4=""),"Indicare forma e posti",IF(AC4>D4,"Troppi invitati",IF(AC4<D4,"Posti liberi: "&(D4-AC4),"OK"))))
A5: 4 | B5: Tavolo 4 | C5: Tondo | D5: 10 | E5: Marta Giordano | F5: Simone Giordano | G5: Alessio Rizzo | H5: Luca De | I5: Francesca Rossi | J5: Nicola Coppola | K5: Martina Caruso | L5: Stefano De | M5: Alessio Longo | N5: Giorgio Giordano | AC5: =COUNTA(E5:AB5) | AD5: =IF(AND(C5="",D5="",AC5=0),"",IF(OR(C5="",D5=""),"Indicare forma e posti",IF(AC5>D5,"Troppi invitati",IF(AC5<D5,"Posti liberi: "&(D5-AC5),"OK"))))
A6: 5 | B6: Tavolo 5 | C6: Tondo | D6: 11 | E6: Chiara Romano | F6: Stefano Moretti | G6: Beatrice De | H6: Silvia Martinelli | I6: Gabriele Giordano | J6: Andrea Galli | K6: Alice Romano | L6: Valentina De | M6: Elena Gallo | N6: Marco Leone | O6: Matteo Barbieri | AC6: =COUNTA(E6:AB6) | AD6: =IF(AND(C6="",D6="",AC6=0),"",IF(OR(C6="",D6=""),"Indicare forma e posti",IF(AC6>D6,"Troppi invitati",IF(AC6<D6,"Posti liberi: "&(D6-AC6),"OK"))))
A7: 6 | B7: Tavolo 6 | C7: Tondo | D7: 10 | E7: Elisa Rizzo | F7: Giulia Martini | G7: Chiara Costa | H7: Laura Gallo | I7: Paolo Rizzo | J7: Davide De | K7: Marco Fontana | L7: Alice Giordano | M7: Nicola Moretti | N7: Paolo Leone | AC7: =COUNTA(E7:AB7) | AD7: =IF(AND(C7="",D7="",AC7=0),"",IF(OR(C7="",D7=""),"Indicare forma e posti",IF(AC7>D7,"Troppi invitati",IF(AC7<D7,"Posti liberi: "&(D7-AC7),"OK"))))
A8: 7 | B8: Tavolo 7 | C8: Tondo | D8: 11 | E8: Martina De | F8: Fabio Giordano | G8: Matteo Ferrari | H8: Alessio Rossi | I8: Chiara Ferrara | J8: Paola Marino | K8: Giorgio Russo | L8: Riccardo Martinelli | M8: Laura Vitale | N8: Daniele Gallo | O8: Davide Rinaldi | AC8: =COUNTA(E8:AB8) | AD8: =IF(AND(C8="",D8="",AC8=0),"",IF(OR(C8="",D8=""),"Indicare forma e posti",IF(AC8>D8,"Troppi invitati",IF(AC8<D8,"Posti liberi: "&(D8-AC8),"OK"))))
A9: 8 | B9: Tavolo 8 | C9: Tondo | D9: 9 | E9: Valentina Santoro | F9: Silvia Barbieri | G9: Fabio Luca | H9: Fabio Bianchi | I9: Elena Martinelli | J9: Matteo De | K9: Paolo Ricci | L9: Paolo Colombo | M9: Marta Coppola | AC9: =COUNTA(E9:AB9) | AD9: =IF(AND(C9="",D9="",AC9=0),"",IF(OR(C9="",D9=""),"Indicare forma e posti",IF(AC9>D9,"Troppi invitati",IF(AC9<D9,"Posti liberi: "&(D9-AC9),"OK"))))
A10: 9 | B10: Tavolo 9 | C10: Tondo | D10: 10 | E10: Alessio Lombardi | F10: Enrico Rinaldi | G10: Marta Lombardi | H10: Nicola Ferrari | I10: Alice Colombo | J10: Alice Vitale | K10: Simone Conti | L10: Giulia Serra | M10: Alessio Santoro | N10: Fabio Caruso | AC10: =COUNTA(E10:AB10) | AD10: =IF(AND(C10="",D10="",AC10=0),"",IF(OR(C10="",D10=""),"Indicare forma e posti",IF(AC10>D10,"Troppi invitati",IF(AC10<D10,"Posti liberi: "&(D10-AC10),"OK"))))
A11: 10 | B11: Tavolo 10 | C11: Tondo | D11: 9 | E11: Fabio Gallo | F11: Giulia Santoro | G11: Giorgio Bianchi | H11: Silvia Mancini | I11: Davide Giordano | J11: Valentina Moretti | K11: Elisa Greco | L11: Sara Luca | M11: Giorgio Gallo | AC11: =COUNTA(E11:AB11) | AD11: =IF(AND(C11="",D11="",AC11=0),"",IF(OR(C11="",D11=""),"Indicare forma e posti",IF(AC11>D11,"Troppi invitati",IF(AC11<D11,"Posti liberi: "&(D11-AC11),"OK"))))
A12: 11 | B12: Tavolo 11 | C12: Tondo | D12: 10 | E12: Riccardo Romano | F12: Beatrice Bianchi | G12: Laura Leone | H12: Paolo Vitale | I12: Gabriele Colombo | J12: Enrico Serra | K12: Luca Longo | L12: Irene Mancini | M12: Enrico Fontana | N12: Matteo Leone | AC12: =COUNTA(E12:AB12) | AD12: =IF(AND(C12="",D12="",AC12=0),"",IF(OR(C12="",D12=""),"Indicare forma e posti",IF(AC12>D12,"Troppi invitati",IF(AC12<D12,"Posti liberi: "&(D12-AC12),"OK"))))
A13: 12 | B13: Imperiale | C13: Rettangolare | D13: 5 | E13: Sara Gentile | F13: Chiara De | G13: Paolo Luca | H13: Simone Serra | I13: Daniele Giordano | AC13: =COUNTA(E13:AB13) | AD13: =IF(AND(C13="",D13="",AC13=0),"",IF(OR(C13="",D13=""),"Indicare forma e posti",IF(AC13>D13,"Troppi invitati",IF(AC13<D13,"Posti liberi: "&(D13-AC13),"OK"))))
A14: 13 | AC14: =COUNTA(E14:AB14) | AD14: =IF(AND(C14="",D14="",AC14=0),"",IF(OR(C14="",D14=""),"Indicare forma e posti",IF(AC14>D14,"Troppi invitati",IF(AC14<D14,"Posti liberi: "&(D14-AC14),"OK"))))
A15: 14 | AC15: =COUNTA(E15:AB15) | AD15: =IF(AND(C15="",D15="",AC15=0),"",IF(OR(C15="",D15=""),"Indicare forma e posti",IF(AC15>D15,"Troppi invitati",IF(AC15<D15,"Posti liberi: "&(D15-AC15),"OK"))))
A16: 15 | AC16: =COUNTA(E16:AB16) | AD16: =IF(AND(C16="",D16="",AC16=0),"",IF(OR(C16="",D16=""),"Indicare forma e posti",IF(AC16>D16,"Troppi invitati",IF(AC16<D16,"Posti liberi: "&(D16-AC16),"OK"))))
A17: 16 | AC17: =COUNTA(E17:AB17) | AD17: =IF(AND(C17="",D17="",AC17=0),"",IF(OR(C17="",D17=""),"Indicare forma e posti",IF(AC17>D17,"Troppi invitati",IF(AC17<D17,"Posti liberi: "&(D17-AC17),"OK"))))
A18: 17 | AC18: =COUNTA(E18:AB18) | AD18: =IF(AND(C18="",D18="",AC18=0),"",IF(OR(C18="",D18=""),"Indicare forma e posti",IF(AC18>D18,"Troppi invitati",IF(AC18<D18,"Posti liberi: "&(D18-AC18),"OK"))))
A19: 18 | AC19: =COUNTA(E19:AB19) | AD19: =IF(AND(C19="",D19="",AC19=0),"",IF(OR(C19="",D19=""),"Indicare forma e posti",IF(AC19>D19,"Troppi invitati",IF(AC19<D19,"Posti liberi: "&(D19-AC19),"OK"))))
A20: 19 | AC20: =COUNTA(E20:AB20) | AD20: =IF(AND(C20="",D20="",AC20=0),"",IF(OR(C20="",D20=""),"Indicare forma e posti",IF(AC20>D20,"Troppi invitati",IF(AC20<D20,"Posti liberi: "&(D20-AC20),"OK"))))
A21: 20 | AC21: =COUNTA(E21:AB21) | AD21: =IF(AND(C21="",D21="",AC21=0),"",IF(OR(C21="",D21=""),"Indicare forma e posti",IF(AC21>D21,"Troppi invitati",IF(AC21<D21,"Posti liberi: "&(D21-AC21),"OK"))))
A22: 21 | AC22: =COUNTA(E22:AB22) | AD22: =IF(AND(C22="",D22="",AC22=0),"",IF(OR(C22="",D22=""),"Indicare forma e posti",IF(AC22>D22,"Troppi invitati",IF(AC22<D22,"Posti liberi: "&(D22-AC22),"OK"))))
A23: 22 | AC23: =COUNTA(E23:AB23) | AD23: =IF(AND(C23="",D23="",AC23=0),"",IF(OR(C23="",D23=""),"Indicare forma e posti",IF(AC23>D23,"Troppi invitati",IF(AC23<D23,"Posti liberi: "&(D23-AC23),"OK"))))
A24: 23 | AC24: =COUNTA(E24:AB24) | AD24: =IF(AND(C24="",D24="",AC24=0),"",IF(OR(C24="",D24=""),"Indicare forma e posti",IF(AC24>D24,"Troppi invitati",IF(AC24<D24,"Posti liberi: "&(D24-AC24),"OK"))))
A25: 24 | AC25: =COUNTA(E25:AB25) | AD25: =IF(AND(C25="",D25="",AC25=0),"",IF(OR(C25="",D25=""),"Indicare forma e posti",IF(AC25>D25,"Troppi invitati",IF(AC25<D25,"Posti liberi: "&(D25-AC25),"OK"))))
... A41: 40 | AC41: =COUNTA(E41:AB41) | AD41: =IF(AND(C41="",D41="",AC41=0),"",IF(OR(C41="",D41=""),"Indicare forma e posti",IF(AC41>D41,"Troppi invitati",IF(AC41<D41,"Posti liberi: "&(D41-AC41),"OK"))))

Sheet Leggimi
B2: L A S T E L L A
B3: N E W C O N C E P T B A N Q U E T I N G
B5: Elenco invitati e disposizione ai tavoli
B7: Come si compila | C7: Compilate i due fogli in ordine: prima «Invitati», poi «Tavoli». Poi rimandateci il file così com'è (non cambiate nomi dei fogli o l'ordine delle colonne).
B8: 1 · Foglio «Invitati» | C8: Una riga per persona: Nome, Cognome, Fascia (Adulto / Bambino / Neonato) e, se serve, Dieta. Mettete una X nelle colonne delle ALLERGIE (rosso) e delle INTOLLERANZE (giallo) che riguardano quella persona. Per tutto il resto usate le due colonne di testo a destra.
B9: Fascia | C9: Adulto · Bambino (circa 3-10 anni) · Neonato (0-2 anni). Bambini e neonati occupano comunque un posto a tavola.
B10: Dieta | C10: Vegetariano · Vegano · Fruttariano · Pescetariano · Crudista · Halal · Kosher. Lasciate vuoto se nessuna.
B11: Allergie | C11: Sono i 14 allergeni a dichiarazione obbligatoria (Reg. UE 1169/2011). Una allergia è un rischio per la salute: segnalatela sempre, anche se lieve.
B12: Intolleranze | C12: Celiachia, lattosio, nichel, istamina, fruttosio, favismo. Se manca la vostra, scrivetela in «Altre allergie / intolleranze».
B13: 2 · Foglio «Tavoli» | C13: Per ogni tavolo: scegliete la FORMA (Tondo o Rettangolare/imperiale), indicate il NUMERO DI POSTI e poi, nelle colonne «Posto 1…», scegliete dal menu a tendina il nome dell'invitato (l'elenco si alimenta da «Invitati»).
B14: Tavoli tondi | C14: Da un minimo di 8 a un massimo di 11 persone per tavolo (bambini e neonati compresi). I posti sono numerati in senso orario partendo dal posto 1.
B15: Tavoli rettangolari | C15: I posti si dividono sui due lati lunghi: dal posto 1 si riempie il lato superiore da sinistra a destra (metà posti, +1 se dispari), poi il lato inferiore da sinistra a destra.
B16: Controlli automatici | C16: Colonna «Controllo»: segnala posti liberi / troppi invitati. Un nome ripetuto in due posti diventa rosso. In «Invitati» l'ultima colonna dice se la persona è già assegnata a un tavolo.
B17: Scadenze | C17: Le scelte di allestimento vanno confermate entro la data indicata dal vostro referente. Elenco invitati e tavoli: inviateci una prima versione appena possibile, potrete aggiornarla fino a pochi giorni prima dell'evento.
B19: Riepilogo automatico
B20: Invitati inseriti | C20: =SUMPRODUCT(--(Invitati!$A$2:$A$301&Invitati!$B$2:$B$301<>""))
B21: di cui adulti | C21: =COUNTIF(Invitati!$C$2:$C$301,"Adulto")
B22: di cui bambini | C22: =COUNTIF(Invitati!$C$2:$C$301,"Bambino")
B23: di cui neonati | C23: =COUNTIF(Invitati!$C$2:$C$301,"Neonato")
B24: Tavoli compilati | C24: =COUNTIF(Tavoli!$D$2:$D$41,">0")
B25: Posti totali | C25: =SUM(Tavoli!$D$2:$D$41)
B26: Invitati ancora da assegnare | C26: =COUNTIF(Invitati!$AB$2:$AB$301,"Da assegnare")
B27: Segnalazioni di allergia (totale X) | C27: =COUNTIF(Invitati!$E$2:$R$301,"X")
B29: Per qualsiasi dubbio: info@cateringlastella.com · +39 339 385 8184
